Workbook
Name UPDATE: 'Data Sheet'!$E$1

Sheet Profit & Loss
A1: ='Data Sheet'!B1 -> ITC LTD | H1: =UPDATE
A3: Narration | B3: ='Data Sheet'!B16 -> 42460 | C3: ='Data Sheet'!C16 -> 42825 | D3: ='Data Sheet'!D16 -> 43190 | E3: ='Data Sheet'!E16 -> 43555 | F3: ='Data Sheet'!F16 -> 43921 | G3: ='Data Sheet'!G16 -> 44286 | H3: ='Data Sheet'!H16 -> 44651 | I3: ='Data Sheet'!I16 -> 45016 | ... K3: ='Data Sheet'!K16 -> 45747 | L3: Trailing | M3: Best Case | N3: Worst Case
A4: Sales | B4: ='Data Sheet'!B17 -> 39192.1 | C4: ='Data Sheet'!C17 -> 42767.6 | D4: ='Data Sheet'!D17 -> 43448.94 | E4: ='Data Sheet'!E17 -> 48339.58 | F4: ='Data Sheet'!F17 -> 49387.7 | G4: ='Data Sheet'!G17 -> 49257.45 | H4: ='Data Sheet'!H17 -> 60644.54 | I4: ='Data Sheet'!I17 -> 70919.03 | ... K4: ='Data Sheet'!K17 -> 75323.34 | L4: =SUM(Quarters!H4:K4) -> 79040.32 | M4: =$K4+M23*K4 -> 83518.968 | N4: =$K4+N23*L4 -> 81245.656
A5: Expenses | B5: =SUM('Data Sheet'!B18,'Data Sheet'!B20:B24, -1*'Data Sheet'!B19) -> 24660.61 | C5: =SUM('Data Sheet'!C18,'Data Sheet'!C20:C24, -1*'Data Sheet'!C19) -> 27298.09 | D5: =SUM('Data Sheet'!D18,'Data Sheet'!D20:D24, -1*'Data Sheet'!D19) -> 26928.35 | E5: =SUM('Data Sheet'!E18,'Data Sheet'!E20:E24, -1*'Data Sheet'!E19) -> 29802.19 | F5: =SUM('Data Sheet'!F18,'Data Sheet'!F20:F24, -1*'Data Sheet'!F19) -> 30044.16 | G5: =SUM('Data Sheet'!G18,'Data Sheet'!G20:G24, -1*'Data Sheet'!G19) -> 32192.67 | H5: =SUM('Data Sheet'!H18,'Data Sheet'!H20:H24, -1*'Data Sheet'!H19) -> 40021.39 | I5: =SUM('Data Sheet'!I18,'Data Sheet'!I20:I24, -1*'Data Sheet'!I19) -> 45214.77 | ... K5: =SUM('Data Sheet'!K18,'Data Sheet'!K20:K24, -1*'Data Sheet'!K19) -> 49483.89 | L5: =SUM(Quarters!H5:K5) -> 52790.48 | M5: =M4-M6 -> 53597.014 | N5: =N4-N6 -> 54263.409
A6: Operating Profit | B6: =B4-B5 -> 14531.49 | C6: =C4-C5 -> 15469.51 | D6: =D4-D5 -> 16520.59 | E6: =E4-E5 -> 18537.39 | F6: =F4-F5 -> 19343.54 | G6: =G4-G5 -> 17064.78 | H6: =H4-H5 -> 20623.15 | I6: =I4-I5 -> 25704.26 | ... K6: =K4-K5 -> 25839.45 | L6: =SUM(Quarters!H6:K6) -> 26249.84 | M6: =M4*M24 -> 29921.955 | N6: =N4*N24 -> 26982.247
A7: Other Income | B7: ='Data Sheet'!B25 -> 1483.11 | C7: ='Data Sheet'!C25 -> 1758.63 | D7: ='Data Sheet'!D25 -> 2239.81 | E7: ='Data Sheet'!E25 -> 2080.44 | F7: ='Data Sheet'!F25 -> 2417.32 | G7: ='Data Sheet'!G25 -> 2576.95 | H7: ='Data Sheet'!H25 -> 1909.72 | I7: ='Data Sheet'!I25 -> 2097.64 | ... K7: ='Data Sheet'!K25 -> 17794.88 | L7: =SUM(Quarters!H7:K7) -> 17635.96 | M7: 0 | N7: 0
A8: Depreciation | B8: ='Data Sheet'!B26 -> 1077.4 | C8: ='Data Sheet'!C26 -> 1152.79 | D8: ='Data Sheet'!D26 -> 1236.28 | E8: ='Data Sheet'!E26 -> 1396.61 | F8: ='Data Sheet'!F26 -> 1644.91 | G8: ='Data Sheet'!G26 -> 1645.59 | H8: ='Data Sheet'!H26 -> 1732.41 | I8: ='Data Sheet'!I26 -> 1809.01 | ... K8: ='Data Sheet'!K26 -> 1646.32 | L8: =SUM(Quarters!H8:K8) -> 1666.15 | M8: =+$L8 -> 1666.15 | N8: =+$L8 -> 1666.15
A9: Interest | B9: ='Data Sheet'!B27 -> 78.13 | C9: ='Data Sheet'!C27 -> 49.03 | D9: ='Data Sheet'!D27 -> 115.01 | E9: ='Data Sheet'!E27 -> 71.4 | F9: ='Data Sheet'!F27 -> 81.38 | G9: ='Data Sheet'!G27 -> 57.97 | H9: ='Data Sheet'!H27 -> 59.99 | I9: ='Data Sheet'!I27 -> 77.77 | ... K9: ='Data Sheet'!K27 -> 45.06 | L9: =SUM(Quarters!H9:K9) -> 51.93 | M9: =+$L9 -> 51.93 | N9: =+$L9 -> 51.93
A10: Profit before tax | B10: ='Data Sheet'!B28 -> 14859.07 | C10: ='Data Sheet'!C28 -> 16026.32 | D10: ='Data Sheet'!D28 -> 17409.11 | E10: ='Data Sheet'!E28 -> 19149.82 | F10: ='Data Sheet'!F28 -> 20034.57 | G10: ='Data Sheet'!G28 -> 17938.17 | H10: ='Data Sheet'!H28 -> 20740.47 | I10: ='Data Sheet'!I28 -> 25915.12 | ... K10: ='Data Sheet'!K28 -> 41942.95 | L10: =SUM(Quarters!H10:K10) -> 42167.72 | M10: =M6+M7-SUM(M8:M9) -> 28203.875 | N10: =N6+N7-SUM(N8:N9) -> 25264.167
A11: Tax | B11: ='Data Sheet'!B29 -> 5358.21 | C11: ='Data Sheet'!C29 -> 5549.09 | D11: ='Data Sheet'!D29 -> 5916.43 | E11: ='Data Sheet'!E29 -> 6313.92 | F11: ='Data Sheet'!F29 -> 4441.79 | G11: ='Data Sheet'!G29 -> 4555.29 | H11: ='Data Sheet'!H29 -> 5237.34 | I11: ='Data Sheet'!I29 -> 6438.4 | ... K11: ='Data Sheet'!K29 -> 6890.47 | L11: =SUM(Quarters!H11:K11) -> 6948.82 | M11: =IF($L10>0,$L11/$L10,0) -> 0.16479003 | N11: =IF($L10>0,$L11/$L10,0) -> 0.16479003
A12: Net profit | B12: ='Data Sheet'!B30 -> 9344.45 | C12: ='Data Sheet'!C30 -> 10289.44 | D12: ='Data Sheet'!D30 -> 11271.2 | E12: ='Data Sheet'!E30 -> 12592.33 | F12: ='Data Sheet'!F30 -> 15306.23 | G12: ='Data Sheet'!G30 -> 13161.19 | H12: ='Data Sheet'!H30 -> 15242.66 | I12: ='Data Sheet'!I30 -> 19191.66 | ... K12: ='Data Sheet'!K30 -> 34746.63 | L12: =SUM(Quarters!H12:K12) -> 34899.24 | M12: =M10-M11*M10 -> 23556.157 | N12: =N10-N11*N10 -> 21100.884
A13: EPS | B13: =IF('Data Sheet'!B93>0,B12/'Data Sheet'!B93,0) -> 7.7413676 | C13: =IF('Data Sheet'!C93>0,C12/'Data Sheet'!C93,0) -> 8.4704875 | D13: =IF('Data Sheet'!D93>0,D12/'Data Sheet'!D93,0) -> 9.2354334 | E13: =IF('Data Sheet'!E93>0,E12/'Data Sheet'!E93,0) -> 10.272242 | F13: =IF('Data Sheet'!F93>0,F12/'Data Sheet'!F93,0) -> 12.451986 | G13: =IF('Data Sheet'!G93>0,G12/'Data Sheet'!G93,0) -> 10.692505 | H13: =IF('Data Sheet'!H93>0,H12/'Data Sheet'!H93,0) -> 12.368976 | I13: =IF('Data Sheet'!I93>0,I12/'Data Sheet'!I93,0) -> 15.442276 | ... K13: =IF('Data Sheet'!K93>0,K12/'Data Sheet'!K93,0) -> 27.765984 | L13: =IF('Data Sheet'!$B6>0,'Profit & Loss'!L12/'Data Sheet'!$B6,0) -> 27.85661 | M13: =IF('Data Sheet'!$B6>0,'Profit & Loss'!M12/'Data Sheet'!$B6,0) -> 18.802549 | N13: =IF('Data Sheet'!$B6>0,'Profit & Loss'!N12/'Data Sheet'!$B6,0) -> 16.842748
A14: Price to earning | B14: =IF(B15>0,B15/B13,"") -> 26.497902 | C14: =IF(C15>0,C15/C13,"") -> 31.019466 | D14: =IF(D15>0,D15/D13,"") -> 25.93273 | E14: =IF(E15>0,E15/E13,"") -> 27.12553 | F14: =IF(F15>0,F15/F13,"") -> 12.925649 | G14: =IF(G15>0,G15/G13,"") -> 19.155475 | H14: =IF(H15>0,H15/H13,"") -> 18.995914 | I14: =IF(I15>0,I15/I13,"") -> 23.2796 | ... K14: =IF(K15>0,K15/K13,"") -> 14.757266 | L14: =IF(L13>0,L15/L13,0) -> 14.852848 | M14: =M25 -> 19.348138 | N14: =N25 -> 14.852848
A15: Price | B15: ='Data Sheet'!B90 -> 205.13 | C15: ='Data Sheet'!C90 -> 262.75 | D15: ='Data Sheet'!D90 -> 239.5 | E15: ='Data Sheet'!E90 -> 278.64 | F15: ='Data Sheet'!F90 -> 160.95 | G15: ='Data Sheet'!G90 -> 204.82 | H15: ='Data Sheet'!H90 -> 234.96 | I15: ='Data Sheet'!I90 -> 359.49 | ... K15: ='Data Sheet'!K90 -> 409.75 | L15: ='Data Sheet'!B8 -> 413.75 | M15: =M13*M14 -> 363.79432 | N15: =N13*N14 -> 250.16278
A17: RATIOS:
A18: Dividend Payout | B18: =IF('Data Sheet'!B30>0, 'Data Sheet'!B31/'Data Sheet'!B30, 0) -> 0.73199814 | C18: =IF('Data Sheet'!C30>0, 'Data Sheet'!C31/'Data Sheet'!C30, 0) -> 0.56077104 | D18: =IF('Data Sheet'!D30>0, 'Data Sheet'!D31/'Data Sheet'!D30, 0) -> 0.5576345 | E18: =IF('Data Sheet'!E30>0, 'Data Sheet'!E31/'Data Sheet'!E30, 0) -> 0.55976138 | F18: =IF('Data Sheet'!F30>0, 'Data Sheet'!F31/'Data Sheet'!F30, 0) -> 0.81513083 | G18: =IF('Data Sheet'!G30>0, 'Data Sheet'!G31/'Data Sheet'!G30, 0) -> 1.0053772 | H18: =IF('Data Sheet'!H30>0, 'Data Sheet'!H31/'Data Sheet'!H30, 0) -> 0.92974586 | I18: =IF('Data Sheet'!I30>0, 'Data Sheet'!I31/'Data Sheet'!I30, 0) -> 1.0037381 | ... K18: =IF('Data Sheet'!K30>0, 'Data Sheet'!K31/'Data Sheet'!K30, 0) -> 0.51681933
A19: OPM | B19: =IF(B6>0,B6/B4,0) -> 0.370776 | C19: =IF(C6>0,C6/C4,0) -> 0.36171097 | D19: =IF(D6>0,D6/D4,0) -> 0.38022999 | E19: =IF(E6>0,E6/E4,0) -> 0.38348265 | F19: =IF(F6>0,F6/F4,0) -> 0.39166716 | G19: =IF(G6>0,G6/G4,0) -> 0.34644059 | H19: =IF(H6>0,H6/H4,0) -> 0.34006606 | I19: =IF(I6>0,I6/I4,0) -> 0.36244517 | ... L19: =IF(L6>0,L6/L4,0) -> 0.33210696
G22: TRENDS: | H22: 10 YEARS | I22: 7 YEARS | J22: 5 YEARS | K22: 3 YEARS | L22: RECENT | M22: BEST | N22: WORST
G23: Sales Growth | H23: =IF(B4=0,"",POWER($K4/B4,1/9)-1) -> 0.075290157 | I23: =IF(D4=0,"",POWER($K4/D4,1/7)-1) -> 0.081772082 | J23: =IF(F4=0,"",POWER($K4/F4,1/5)-1) -> 0.088083322 | K23: =IF(H4=0,"",POWER($K4/H4, 1/3)-1) -> 0.074927782 | L23: =IF(ISERROR(MAX(IF(J4=0,"",(K4-J4)/J4),IF(K4=0,"",(L4-K4)/K4))),"",MAX(IF(J4=0,"",(K4-J4)/J4),IF(K4=0,"",(L4-K4)/K4))) -> 0.10880596 | M23: =MAX(K23:L23) -> 0.10880596 | N23: =MIN(H23:L23) -> 0.074927782
G24: OPM | H24: =IF(SUM(B4:$K$4)=0,"",SUMPRODUCT(B19:$K$19,B4:$K$4)/SUM(B4:$K$4)) -> 0.36333562 | I24: =IF(SUM(E4:$K$4)=0,"",SUMPRODUCT(E19:$K$19,E4:$K$4)/SUM(E4:$K$4)) -> 0.36106877 | J24: =IF(SUM(G4:$K$4)=0,"",SUMPRODUCT(G19:$K$19,G4:$K$4)/SUM(G4:$K$4)) -> 0.35306244 | K24: =IF(SUM(I4:$K$4)=0, "", SUMPRODUCT(I19:$K$19,I4:$K$4)/SUM(I4:$K$4)) -> 0.35826538 | L24: =L19 -> 0.33210696 | M24: =MAX(K24:L24) -> 0.35826538 | N24: =MIN(H24:L24) -> 0.33210696
G25: Price to Earning | H25: =IF(ISERROR(AVERAGEIF(B14:$L14,">0")),"",AVERAGEIF(B14:$L14,">0")) -> 21.731383 | I25: =IF(ISERROR(AVERAGEIF(E14:$L14,">0")),"",AVERAGEIF(E14:$L14,">0")) -> 19.44939 | J25: =IF(ISERROR(AVERAGEIF(G14:$L14,">0")),"",AVERAGEIF(G14:$L14,">0")) -> 19.257323 | K25: =IF(ISERROR(AVERAGEIF(I14:$L14,">0")),"",AVERAGEIF(I14:$L14,">0")) -> 19.348138 | L25: =L14 -> 14.852848 | M25: =MAX(K25:L25) -> 19.348138 | N25: =MIN(H25:L25) -> 14.852848

Sheet Historical Financial Statemen
B3: ="Historical Financial Statement - "&'Balance Sheet'!A1 -> Historical Financial Statement - ITC LTD
B4: Years | C4: ='Balance Sheet'!B3 -> 42460 | D4: ='Balance Sheet'!C3 -> 42825 | E4: ='Balance Sheet'!D3 -> 43190 | F4: ='Balance Sheet'!E3 -> 43555 | G4: ='Balance Sheet'!F3 -> 43921 | H4: ='Balance Sheet'!G3 -> 44286 | I4: ='Balance Sheet'!H3 -> 44651 | J4: ='Balance Sheet'!I3 -> 45016 | ... L4: ='Balance Sheet'!K3 -> 45747 | M4: LTM
B6: Income Statement
B7: Sales | C7: =IFERROR('Data Sheet'!B17,0) -> 39192.1 | D7: =IFERROR('Data Sheet'!C17,0) -> 42767.6 | E7: =IFERROR('Data Sheet'!D17,0) -> 43448.94 | F7: =IFERROR('Data Sheet'!E17,0) -> 48339.58 | G7: =IFERROR('Data Sheet'!F17,0) -> 49387.7 | H7: =IFERROR('Data Sheet'!G17,0) -> 49257.45 | I7: =IFERROR('Data Sheet'!H17,0) -> 60644.54 | J7: =IFERROR('Data Sheet'!I17,0) -> 70919.03 | ... L7: =IFERROR('Data Sheet'!K17,0) -> 75323.34 | M7: =IFERROR(SUM(Quarters!J4:K4),0) -> 40259.79
B8: Sales Growth | F8: - | G8: =(G7-F7)/F7 -> 0.021682439 | H8: =(H7-G7)/G7 -> -0.0026372963 | I8: =(I7-H7)/H7 -> 0.23117498 | J8: =(J7-I7)/I7 -> 0.16942152 | K8: =(K7-J7)/J7 -> -0.042119724 | L8: =(L7-K7)/K7 -> 0.10880596 | M8: =(M7-L7)/L7 -> -0.46550711
B10: COGS | C10: =IFERROR(SUM('Data Sheet'!B18:B23),0) -> 23815.48 | D10: =IFERROR(SUM('Data Sheet'!C18:C23),0) -> 24943.72 | E10: =IFERROR(SUM('Data Sheet'!D18:D23),0) -> 23866.85 | F10: =IFERROR(SUM('Data Sheet'!E18:E23),0) -> 29168.72 | G10: =IFERROR(SUM('Data Sheet'!F18:F23),0) -> 30225.29 | H10: =IFERROR(SUM('Data Sheet'!G18:G23),0) -> 32408.82 | I10: =IFERROR(SUM('Data Sheet'!H18:H23),0) -> 40283.44 | J10: =IFERROR(SUM('Data Sheet'!I18:I23),0) -> 44623.39 | ... L10: =IFERROR(SUM('Data Sheet'!K18:K23),0) -> 48713.8 | M10: =IFERROR(Quarters!D5,0) -> 11320.23
B11: COGS % Sales | C11: =C10/C7 -> 0.60766022 | D11: =D10/D7 -> 0.58323871 | E11: =E10/E7 -> 0.54930799 | F11: =F10/F7 -> 0.60341277 | G11: =G10/G7 -> 0.61200036 | H11: =H10/H7 -> 0.65794758 | I11: =I10/I7 -> 0.66425502 | J11: =J10/J7 -> 0.62921602 | ... M11: =M10/M7 -> 0.28117956
B13: Gross Profit | C13: =C7-C10 -> 15376.62 | D13: =D7-D10 -> 17823.88 | E13: =E7-E10 -> 19582.09 | F13: =F7-F10 -> 19170.86 | G13: =G7-G10 -> 19162.41 | H13: =H7-H10 -> 16848.63 | I13: =I7-I10 -> 20361.1 | J13: =J7-J10 -> 26295.64 | ... M13: =M7-M10 -> 28939.56
B14: Gross Profit % Sales | C14: =C13/C7 -> 0.39233978 | D14: =D13/D7 -> 0.41676129 | E14: =E13/E7 -> 0.45069201 | F14: =F13/F7 -> 0.39658723 | G14: =G13/G7 -> 0.38799964 | H14: =H13/H7 -> 0.34205242 | I14: =I13/I7 -> 0.33574498 | J14: =J13/J7 -> 0.37078398 | ... M14: =M13/M7 -> 0.71882044
B16: Sales &General Expenses | C16: =IFERROR(SUM('Data Sheet'!B24:B25),0) -> 2719 | D16: =IFERROR(SUM('Data Sheet'!C24:C25),0) -> 2927.86 | E16: =IFERROR(SUM('Data Sheet'!D24:D25),0) -> 3245.79 | F16: =IFERROR(SUM('Data Sheet'!E24:E25),0) -> 3120.29 | G16: =IFERROR(SUM('Data Sheet'!F24:F25),0) -> 3642.45 | H16: =IFERROR(SUM('Data Sheet'!G24:G25),0) -> 3651.34 | I16: =IFERROR(SUM('Data Sheet'!H24:H25),0) -> 3019.67 | J16: =IFERROR(SUM('Data Sheet'!I24:I25),0) -> 3406.2 | ... M16: =IFERROR(SUM('Data Sheet'!L24:L25),0) -> 0
B17: S&G Exp % Sales | C17: =C16/C7 -> 0.069376226 | D17: =D16/D7 -> 0.068459769 | E17: =E16/E7 -> 0.074703549 | F17: =F16/F7 -> 0.064549382 | G17: =G16/G7 -> 0.073752169 | H17: =H16/H7 -> 0.07412767 | I17: =I16/I7 -> 0.049792941 | J17: =J16/J7 -> 0.048029422 | ... M17: =M16/M7 -> 0
B19: EBITDA | C19: =C13-C16 -> 12657.62 | D19: =D13-D16 -> 14896.02 | E19: =E13-E16 -> 16336.3 | F19: =F13-F16 -> 16050.57 | G19: =G13-G16 -> 15519.96 | H19: =H13-H16 -> 13197.29 | I19: =I13-I16 -> 17341.43 | J19: =J13-J16 -> 22889.44 | ... M19: =M13-M16 -> 28939.56
B20: EBITDA Margins | C20: =C19/C7 -> 0.32296356 | D20: =D19/D7 -> 0.34830152 | E20: =E19/E7 -> 0.37598846 | F20: =F19/F7 -> 0.33203785 | G20: =G19/G7 -> 0.31424747 | H20: =H19/H7 -> 0.26792475 | I20: =I19/I7 -> 0.28595204 | J20: =J19/J7 -> 0.32275456 | ... M20: =M19/M7 -> 0.71882044
B22: Interest | C22: =IFERROR('Data Sheet'!B27,0) -> 78.13 | D22: =IFERROR('Data Sheet'!C27,0) -> 49.03 | E22: =IFERROR('Data Sheet'!D27,0) -> 115.01 | F22: =IFERROR('Data Sheet'!E27,0) -> 71.4 | G22: =IFERROR('Data Sheet'!F27,0) -> 81.38 | H22: =IFERROR('Data Sheet'!G27,0) -> 57.97 | I22: =IFERROR('Data Sheet'!H27,0) -> 59.99 | J22: =IFERROR('Data Sheet'!I27,0) -> 77.77 | ... L22: =IFERROR('Data Sheet'!K27,0) -> 45.06 | M22: =IFERROR(Quarters!J9+N11,0) -> 10.91
B23: Int. % Sales | C23: =C22/C7 -> 0.001993514 | D23: =D22/D7 -> 0.0011464286 | E23: =E22/E7 -> 0.0026470151 | F23: =F22/F7 -> 0.0014770505 | G23: =G22/G7 -> 0.0016477787 | H23: =H22/H7 -> 0.0011768778 | I23: =I22/I7 -> 0.00098920694 | J23: =J22/J7 -> 0.0010966027 | ... M23: =M22/M7 -> 0.00027098999
B25: Depreciation | C25: =IFERROR('Data Sheet'!B26,0) -> 1077.4 | D25: =IFERROR('Data Sheet'!C26,0) -> 1152.79 | E25: =IFERROR('Data Sheet'!D26,0) -> 1236.28 | F25: =IFERROR('Data Sheet'!E26,0) -> 1396.61 | G25: =IFERROR('Data Sheet'!F26,0) -> 1644.91 | H25: =IFERROR('Data Sheet'!G26,0) -> 1645.59 | I25: =IFERROR('Data Sheet'!H26,0) -> 1732.41 | J25: =IFERROR('Data Sheet'!I26,0) -> 1809.01 | ... L25: =IFERROR('Data Sheet'!K26,0) -> 1646.32 | M25: =IFERROR(Quarters!J8+N10,0) -> 411.03
B26: Dep. % Sales | C26: =C25/C7 -> 0.027490234 | D26: =D25/D7 -> 0.026954751 | E26: =E25/E7 -> 0.028453629 | F26: =F25/F7 -> 0.028891645 | G26: =G25/G7 -> 0.033306066 | H26: =H25/H7 -> 0.033407941 | I26: =I25/I7 -> 0.028566628 | J26: =J25/J7 -> 0.025508104 | ... M26: =M25/M7 -> 0.010209442
B28: Other Income | C28: =IFERROR('Data Sheet'!B25,0) -> 1483.11 | D28: =IFERROR('Data Sheet'!C25,0) -> 1758.63 | E28: =IFERROR('Data Sheet'!D25,0) -> 2239.81 | F28: =IFERROR('Data Sheet'!E25,0) -> 2080.44 | G28: =IFERROR('Data Sheet'!F25,0) -> 2417.32 | H28: =IFERROR('Data Sheet'!G25,0) -> 2576.95 | I28: =IFERROR('Data Sheet'!H25,0) -> 1909.72 | J28: =IFERROR('Data Sheet'!I25,0) -> 2097.64 | ... L28: =IFERROR('Data Sheet'!K25,0) -> 17794.88 | M28: =IFERROR(Quarters!J7+N9,0) -> 15391.28
B30: Earning Before Tax | C30: =C19+C28-C25-C22 -> 12985.2 | D30: =D19+D28-D25-D22 -> 15452.83 | E30: =E19+E28-E25-E22 -> 17224.82 | F30: =F19+F28-F25-F22 -> 16663 | G30: =G19+G28-G25-G22 -> 16210.99 | H30: =H19+H28-H25-H22 -> 14070.68 | I30: =I19+I28-I25-I22 -> 17458.75 | J30: =J19+J28-J25-J22 -> 23100.3 | ... M30: =M19+M28-M25-M22 -> 43908.9
B31: EBT % Sales | C31: =C30/C7 -> 0.33132187 | D31: =D30/D7 -> 0.36132095 | E31: =E30/E7 -> 0.39643821 | F31: =F30/F7 -> 0.34470717 | G31: =G30/G7 -> 0.32823942 | H31: =H30/H7 -> 0.28565588 | I31: =I30/I7 -> 0.28788659 | J31: =J30/J7 -> 0.32572781 | ... M31: =M30/M7 -> 1.0906391
B34: Tax | C34: =IFERROR('Data Sheet'!B29,0) -> 5358.21 | D34: =IFERROR('Data Sheet'!C29,0) -> 5549.09 | E34: =IFERROR('Data Sheet'!D29,0) -> 5916.43 | F34: =IFERROR('Data Sheet'!E29,0) -> 6313.92 | G34: =IFERROR('Data Sheet'!F29,0) -> 4441.79 | H34: =IFERROR('Data Sheet'!G29,0) -> 4555.29 | I34: =IFERROR('Data Sheet'!H29,0) -> 5237.34 | J34: =IFERROR('Data Sheet'!I29,0) -> 6438.4 | ... L34: =IFERROR('Data Sheet'!K29,0) -> 6890.47 | M34: =IFERROR(Quarters!J11+N13,0) -> 1680.85
B35: Effective Tax Rate | C35: =C34/C30 -> 0.41263977 | D35: =D34/D30 -> 0.35909862 | E35: =E34/E30 -> 0.34348283 | F35: =F34/F30 -> 0.37891856 | G35: =G34/G30 -> 0.27399869 | H35: =H34/H30 -> 0.32374342 | I35: =I34/I30 -> 0.29998368 | J35: =J34/J30 -> 0.278715 | ... M35: =M34/M30 -> 0.038280394
B37: Net Profit | C37: =C30-C34 -> 7626.99 | D37: =D30-D34 -> 9903.74 | E37: =E30-E34 -> 11308.39 | F37: =F30-F34 -> 10349.08 | G37: =G30-G34 -> 11769.2 | H37: =H30-H34 -> 9515.39 | I37: =I30-I34 -> 12221.41 | J37: =J30-J34 -> 16661.9 | ... M37: =M30-M34 -> 42228.05
B38: Proift Margin | C38: =C37/C7 -> 0.19460529 | D38: =D37/D7 -> 0.2315711 | E38: =E37/E7 -> 0.26026849 | F38: =F37/F7 -> 0.21409123 | G38: =G37/G7 -> 0.23830225 | H38: =H37/H7 -> 0.19317667 | I38: =I37/I7 -> 0.20152531 | J38: =J37/J7 -> 0.23494258 | ... M38: =M37/M7 -> 1.048889
B40: No. of Equity Shares | C40: =IFERROR( 'Data Sheet'!B93,0) -> 1207.08 | D40: =IFERROR( 'Data Sheet'!C93,0) -> 1214.74 | E40: =IFERROR( 'Data Sheet'!D93,0) -> 1220.43 | F40: =IFERROR( 'Data Sheet'!E93,0) -> 1225.86 | G40: =IFERROR( 'Data Sheet'!F93,0) -> 1229.22 | H40: =IFERROR( 'Data Sheet'!G93,0) -> 1230.88 | I40: =IFERROR( 'Data Sheet'!H93,0) -> 1232.33 | J40: =IFERROR( 'Data Sheet'!I93,0) -> 1242.8 | ... L40: =IFERROR( 'Data Sheet'!K93,0) -> 1251.41 | M40: =IFERROR( L40,0) -> 1251.41
B42: Earning Per Share | C42: =C37/C40 -> 6.3185456 | D42: =D37/D40 -> 8.152971 | E42: =E37/E40 -> 9.2659063 | F42: =F37/F40 -> 8.4423017 | G42: =G37/G40 -> 9.5745269 | H42: =H37/H40 -> 7.7305586 | I42: =I37/I40 -> 9.9173192 | J42: =J37/J40 -> 13.406743 | ... M42: =M37/M40 -> 33.744376
B44: Dividend Per Sharing | C44: =IFERROR('Data Sheet'!B31/'Data Sheet'!B93,0) -> 5.6666667 | D44: =IFERROR('Data Sheet'!C31/'Data Sheet'!C93,0) -> 4.7500041 | E44: =IFERROR('Data Sheet'!D31/'Data Sheet'!D93,0) -> 5.1499963 | F44: =IFERROR('Data Sheet'!E31/'Data Sheet'!E93,0) -> 5.7500041 | G44: =IFERROR('Data Sheet'!F31/'Data Sheet'!F93,0) -> 10.149998 | H44: =IFERROR('Data Sheet'!G31/'Data Sheet'!G93,0) -> 10.75 | I44: =IFERROR('Data Sheet'!H31/'Data Sheet'!H93,0) -> 11.500004 | J44: =IFERROR('Data Sheet'!I31/'Data Sheet'!I93,0) -> 15.5 | ... L44: =IFERROR('Data Sheet'!K31/'Data Sheet'!K93,0) -> 14.349997 | M44: -
B45: Dividend Payout Ratio | C45: =C44/C42 -> 0.89683086 | D45: =D44/D42 -> 0.58261021 | E45: =E44/E42 -> 0.5558006 | F45: =F44/F42 -> 0.68109436 | G45: =G44/G42 -> 1.0601043 | H45: =H44/H42 -> 1.3905851 | I45: =I44/I42 -> 1.159588 | J45: =J44/J42 -> 1.1561347 | ... L45: =L44/L42 -> 1.1361122 | M45: -
B47: Retained Earning | C47: =IFERROR(IF(C44<C42,1-C45,0),0) -> 0.10316914 | D47: =IFERROR(IF(D44<D42,1-D45,0),0) -> 0.41738979 | E47: =IFERROR(IF(E44<E42,1-E45,0),0) -> 0.4441994 | F47: =IFERROR(IF(F44<F42,1-F45,0),0) -> 0.31890564 | G47: =IFERROR(IF(G44<G42,1-G45,0),0) -> 0 | H47: =IFERROR(IF(H44<H42,1-H45,0),0) -> 0 | I47: =IFERROR(IF(I44<I42,1-I45,0),0) -> 0 | J47: =IFERROR(IF(J44<J42,1-J45,0),0) -> 0 | ... M47: =IFERROR(IF(M44<M42,1-M45,0),0) -> 0
B52: Balance Sheet
B53: Equity Share Capital | C53: ='Balance Sheet'!B4 -> 804.72 | D53: ='Balance Sheet'!C4 -> 1214.74 | E53: ='Balance Sheet'!D4 -> 1220.43 | F53: 1225.86 | G53: 1229.22 | H53: 1230.88 | I53: 1232.33 | J53: 1242.8 | K53: 1248.47 | L53: 1251.41 | M53: -
B54: Reserves | C54: ='Balance Sheet'!B5 -> 41874.8 | D54: ='Balance Sheet'!C5 -> 45198.19 | E54: ='Balance Sheet'!D5 -> 51289.68 | F54: 57915.01 | G54: 64044.04 | H54: 59116.46 | I54: 61223.24 | J54: 67912.46 | K54: 73258.53 | L54: 68778.64 | M54: -
B55: Borrowings | C55: ='Balance Sheet'!B6 -> 83.78 | D55: ='Balance Sheet'!C6 -> 45.72 | E55: ='Balance Sheet'!D6 -> 35.92 | F55: 13.44 | G55: 277.45 | H55: 270.83 | I55: 249.44 | J55: 306.04 | K55: 303.43 | L55: 284.54 | M55: -
B56: Other Liabilities | C56: ='Balance Sheet'!B7 -> 8888.04 | D56: ='Balance Sheet'!C7 -> 9439.67 | E56: ='Balance Sheet'!D7 -> 11694.85 | F56: 12584.73 | G56: 11760.04 | H56: 13142.59 | I56: 14491.01 | J56: 16369.66 | K56: 16943.54 | L56: 17688.11 | M56: -
B57: Total | C57: =SUM(C53:C56) -> 51651.34 | D57: =SUM(D53:D56) -> 55898.32 | E57: =SUM(E53:E56) -> 64240.88 | F57: 71739.04 | G57: 77310.75 | H57: 73760.76 | I57: 77196.02 | J57: 85830.96 | K57: 91753.97 | L57: 88002.7 | M57: -
B59: Net Block | C59: ='Balance Sheet'!B10 -> 15106.63 | D59: ='Balance Sheet'!C10 -> 15893.48 | E59: ='Balance Sheet'!D10 -> 16523.96 | F59: 19374.19 | G59: 21713.34 | H59: 23298.48 | I59: 24231.59 | J59: 25851.27 | K59: 27820.22 | L59: 21954.85 | M59: -
B60: Capital Work in Progress | C60: ='Balance Sheet'!B11 -> 2559.72 | D60: ='Balance Sheet'!C11 -> 3729.89 | E60: ='Balance Sheet'!D11 -> 5508.33 | F60: 4136.42 | G60: 3256.46 | H60: 4011.29 | I60: 3225.54 | J60: 3003.3 | K60: 2860.78 | L60: 1090.91 | M60: -
B61: Investments | C61: ='Balance Sheet'!B12 -> 11747.59 | D61: ='Balance Sheet'!C12 -> 17581.38 | E61: ='Balance Sheet'!D12 -> 22052.86 | F61: 25043.49 | G61: 28663.35 | H61: 24870.87 | I61: 24841.01 | J61: 29415.02 | K61: 31114.02 | L61: 34719.82 | M61: -
B62: Other Assets | C62: =IFERROR('Data Sheet'!B65-'Historical Financial Statemen'!C68,0) -> 14104.84 | D62: =IFERROR('Data Sheet'!C65-'Historical Financial Statemen'!D68,0) -> 10561.01 | E62: =IFERROR('Data Sheet'!D65-'Historical Financial Statemen'!E68,0) -> 12023.17 | F62: =IFERROR('Data Sheet'!E65-'Historical Financial Statemen'!F68,0) -> 15052.38 | G62: =IFERROR('Data Sheet'!F65-'Historical Financial Statemen'!G68,0) -> 7458.93 | H62: =IFERROR('Data Sheet'!G65-'Historical Financial Statemen'!H68,0) -> 6461.94 | I62: =IFERROR('Data Sheet'!H65-'Historical Financial Statemen'!I68,0) -> 9317.31 | J62: =IFERROR('Data Sheet'!I65-'Historical Financial Statemen'!J68,0) -> 10848.02 | ... L62: =IFERROR('Data Sheet'!K65-'Historical Financial Statemen'!L68,0) -> 10525.2 | M62: -
B63: Total Non-Current Assets | C63: =C62+C61+C60+C59 -> 43518.78 | D63: =D62+D61+D60+D59 -> 47765.76 | E63: =E62+E61+E60+E59 -> 56108.32 | F63: =F62+F61+F60+F59 -> 63606.48 | G63: =G62+G61+G60+G59 -> 61092.08 | H63: =H62+H61+H60+H59 -> 58642.58 | I63: =I62+I61+I60+I59 -> 61615.45 | J63: =J62+J61+J60+J59 -> 69117.61 | ... L63: =L62+L61+L60+L59 -> 68290.78 | M63: -
...

Sheet Ratio Analysis
B3: ="Ratio Analysis - "&'Balance Sheet'!A1 -> Ratio Analysis - ITC LTD
B4: Years | C4: ='Historical Financial Statemen'!C4 -> 42460 | D4: ='Historical Financial Statemen'!D4 -> 42825 | E4: ='Historical Financial Statemen'!E4 -> 43190 | F4: ='Historical Financial Statemen'!F4 -> 43555 | G4: ='Balance Sheet'!F3 -> 43921 | H4: ='Balance Sheet'!G3 -> 44286 | I4: ='Balance Sheet'!H3 -> 44651 | J4: ='Balance Sheet'!I3 -> 45016 | K4: ='Balance Sheet'!J3 -> 45382 | L4: ='Balance Sheet'!K3 -> 45747
B6: Sales Growth | C6: =IFERROR('Data Sheet'!B17/'Data Sheet'!A17-1,0) -> 0 | D6: =IFERROR('Data Sheet'!C17/'Data Sheet'!B17-1,0) -> 0.09123012 | E6: =IFERROR('Data Sheet'!D17/'Data Sheet'!C17-1,0) -> 0.015931219 | F6: =IFERROR('Data Sheet'!E17/'Data Sheet'!D17-1,0) -> 0.11256063 | G6: =IFERROR('Data Sheet'!F17/'Data Sheet'!E17-1,0) -> 0.021682439 | H6: =IFERROR('Data Sheet'!G17/'Data Sheet'!F17-1,0) -> -0.0026372963 | I6: =IFERROR('Data Sheet'!H17/'Data Sheet'!G17-1,0) -> 0.23117498 | J6: =IFERROR('Data Sheet'!I17/'Data Sheet'!H17-1,0) -> 0.16942152 | ... L6: =IFERROR('Data Sheet'!K17/'Data Sheet'!J17-1,0) -> 0.10880596
B7: EBITDA Growth | C7: =IFERROR('Historical Financial Statemen'!C19/'Historical Financial Statemen'!B19-1,0) -> 0 | D7: =IFERROR('Historical Financial Statemen'!D19/'Historical Financial Statemen'!C19-1,0) -> 0.17684209 | E7: =IFERROR('Historical Financial Statemen'!E19/'Historical Financial Statemen'!D19-1,0) -> 0.096688914 | F7: =IFERROR('Historical Financial Statemen'!F19/'Historical Financial Statemen'!E19-1,0) -> -0.017490497 | G7: =IFERROR('Historical Financial Statemen'!G19/'Historical Financial Statemen'!F19-1,0) -> -0.033058639 | H7: =IFERROR('Historical Financial Statemen'!H19/'Historical Financial Statemen'!G19-1,0) -> -0.14965696 | I7: =IFERROR('Historical Financial Statemen'!I19/'Historical Financial Statemen'!H19-1,0) -> 0.31401447 | J7: =IFERROR('Historical Financial Statemen'!J19/'Historical Financial Statemen'!I19-1,0) -> 0.31992806 | ... L7: =IFERROR('Historical Financial Statemen'!L19/'Historical Financial Statemen'!K19-1,0) -> -0.68784142
B8: EBIT Growth | C8: =IFERROR(('Historical Financial Statemen'!C19-'Historical Financial Statemen'!C25)/('Historical Financial Statemen'!B19-'Historical Financial Statemen'!B25)-1,0) -> 0 | D8: =IFERROR(('Historical Financial Statemen'!D19-'Historical Financial Statemen'!D25)/('Historical Financial Statemen'!C19-'Historical Financial Statemen'!C25)-1,0) -> 0.18678488 | E8: =IFERROR(('Historical Financial Statemen'!E19-'Historical Financial Statemen'!E25)/('Historical Financial Statemen'!D19-'Historical Financial Statemen'!D25)-1,0) -> 0.098724245 | F8: =IFERROR(('Historical Financial Statemen'!F19-'Historical Financial Statemen'!F25)/('Historical Financial Statemen'!E19-'Historical Financial Statemen'!E25)-1,0) -> -0.029540358 | G8: =IFERROR(('Historical Financial Statemen'!G19-'Historical Financial Statemen'!G25)/('Historical Financial Statemen'!F19-'Historical Financial Statemen'!F25)-1,0) -> -0.05315355 | H8: =IFERROR(('Historical Financial Statemen'!H19-'Historical Financial Statemen'!H25)/('Historical Financial Statemen'!G19-'Historical Financial Statemen'!G25)-1,0) -> -0.16744805 | I8: =IFERROR(('Historical Financial Statemen'!I19-'Historical Financial Statemen'!I25)/('Historical Financial Statemen'!H19-'Historical Financial Statemen'!H25)-1,0) -> 0.35123142 | J8: =IFERROR(('Historical Financial Statemen'!J19-'Historical Financial Statemen'!J25)/('Historical Financial Statemen'!I19-'Historical Financial Statemen'!I25)-1,0) -> 0.35052873 | ... L8: =IFERROR(('Historical Financial Statemen'!L19-'Historical Financial Statemen'!L25)/('Historical Financial Statemen'!K19-'Historical Financial Statemen'!K25)-1,0) -> -0.74764953
B9: Net Profit Growth | C9: =IFERROR('Historical Financial Statemen'!C37/'Historical Financial Statemen'!B37-1,0) -> 0 | D9: =IFERROR('Historical Financial Statemen'!D37/'Historical Financial Statemen'!C37-1,0) -> 0.29851226 | E9: =IFERROR('Historical Financial Statemen'!E37/'Historical Financial Statemen'!D37-1,0) -> 0.14183026 | F9: =IFERROR('Historical Financial Statemen'!F37/'Historical Financial Statemen'!E37-1,0) -> -0.084831705 | G9: =IFERROR('Historical Financial Statemen'!G37/'Historical Financial Statemen'!F37-1,0) -> 0.13722186 | H9: =IFERROR('Historical Financial Statemen'!H37/'Historical Financial Statemen'!G37-1,0) -> -0.1915007 | I9: =IFERROR('Historical Financial Statemen'!I37/'Historical Financial Statemen'!H37-1,0) -> 0.28438351 | J9: =IFERROR('Historical Financial Statemen'!J37/'Historical Financial Statemen'!I37-1,0) -> 0.36333696 | ... L9: =IFERROR('Historical Financial Statemen'!L37/'Historical Financial Statemen'!K37-1,0) -> -0.052685077
B10: Dividend Growth | C10: =IFERROR('Historical Financial Statemen'!C44/'Historical Financial Statemen'!B44-1,0) -> 0 | D10: =IFERROR('Historical Financial Statemen'!D44/'Historical Financial Statemen'!C44-1,0) -> -0.16176398 | E10: =IFERROR('Historical Financial Statemen'!E44/'Historical Financial Statemen'!D44-1,0) -> 0.084208811 | F10: =IFERROR('Historical Financial Statemen'!F44/'Historical Financial Statemen'!E44-1,0) -> 0.11650645 | G10: =IFERROR('Historical Financial Statemen'!G44/'Historical Financial Statemen'!F44-1,0) -> 0.76521571 | H10: =IFERROR('Historical Financial Statemen'!H44/'Historical Financial Statemen'!G44-1,0) -> 0.059113555 | I10: =IFERROR('Historical Financial Statemen'!I44/'Historical Financial Statemen'!H44-1,0) -> 0.069767819 | J10: =IFERROR('Historical Financial Statemen'!J44/'Historical Financial Statemen'!I44-1,0) -> 0.34782561 | ... L10: =IFERROR('Historical Financial Statemen'!L44/'Historical Financial Statemen'!K44-1,0) -> 0.043636312
B12: Gross Margin | C12: ='Historical Financial Statemen'!C14 -> 0.39233978 | D12: ='Historical Financial Statemen'!D14 -> 0.41676129 | E12: ='Historical Financial Statemen'!E14 -> 0.45069201 | F12: ='Historical Financial Statemen'!F14 -> 0.39658723 | G12: ='Historical Financial Statemen'!G14 -> 0.38799964 | H12: ='Historical Financial Statemen'!H14 -> 0.34205242 | I12: ='Historical Financial Statemen'!I14 -> 0.33574498 | J12: ='Historical Financial Statemen'!J14 -> 0.37078398 | ... L12: ='Historical Financial Statemen'!L14 -> 0.35327085
B13: EBITDA Margin | C13: ='Historical Financial Statemen'!C20 -> 0.32296356 | D13: ='Historical Financial Statemen'!D20 -> 0.34830152 | E13: ='Historical Financial Statemen'!E20 -> 0.37598846 | F13: ='Historical Financial Statemen'!F20 -> 0.33203785 | G13: ='Historical Financial Statemen'!G20 -> 0.31424747 | H13: ='Historical Financial Statemen'!H20 -> 0.26792475 | I13: ='Historical Financial Statemen'!I20 -> 0.28595204 | J13: ='Historical Financial Statemen'!J20 -> 0.32275456 | ... L13: ='Historical Financial Statemen'!L20 -> 0.087532895
B14: EBIT Margin | C14: =IFERROR(('Historical Financial Statemen'!C19-'Historical Financial Statemen'!C25)/'Historical Financial Statemen'!C7,0) -> 0.29547332 | D14: =IFERROR(('Historical Financial Statemen'!D19-'Historical Financial Statemen'!D25)/'Historical Financial Statemen'!D7,0) -> 0.32134677 | E14: =IFERROR(('Historical Financial Statemen'!E19-'Historical Financial Statemen'!E25)/'Historical Financial Statemen'!E7,0) -> 0.34753483 | F14: =IFERROR(('Historical Financial Statemen'!F19-'Historical Financial Statemen'!F25)/'Historical Financial Statemen'!F7,0) -> 0.3031462 | G14: =IFERROR(('Historical Financial Statemen'!G19-'Historical Financial Statemen'!G25)/'Historical Financial Statemen'!G7,0) -> 0.28094141 | H14: =IFERROR(('Historical Financial Statemen'!H19-'Historical Financial Statemen'!H25)/'Historical Financial Statemen'!H7,0) -> 0.23451681 | I14: =IFERROR(('Historical Financial Statemen'!I19-'Historical Financial Statemen'!I25)/'Historical Financial Statemen'!I7,0) -> 0.25738541 | J14: =IFERROR(('Historical Financial Statemen'!J19-'Historical Financial Statemen'!J25)/'Historical Financial Statemen'!J7,0) -> 0.29724645 | ... L14: =IFERROR(('Historical Financial Statemen'!L19-'Historical Financial Statemen'!L25)/'Historical Financial Statemen'!L7,0) -> 0.06567619
B15: Net Profit Margin | C15: ='Historical Financial Statemen'!C38 -> 0.19460529 | D15: ='Historical Financial Statemen'!D38 -> 0.2315711 | E15: ='Historical Financial Statemen'!E38 -> 0.26026849 | F15: ='Historical Financial Statemen'!F38 -> 0.21409123 | G15: ='Historical Financial Statemen'!G38 -> 0.23830225 | H15: ='Historical Financial Statemen'!H38 -> 0.19317667 | I15: ='Historical Financial Statemen'!I38 -> 0.20152531 | J15: ='Historical Financial Statemen'!J38 -> 0.23494258 | ... L15: ='Historical Financial Statemen'!L38 -> 0.20984598
B17: Sales Expenses % Sales | C17: ='Historical Financial Statemen'!C17 -> 0.069376226 | D17: ='Historical Financial Statemen'!D17 -> 0.068459769 | E17: ='Historical Financial Statemen'!E17 -> 0.074703549 | F17: ='Historical Financial Statemen'!F17 -> 0.064549382 | G17: ='Historical Financial Statemen'!G17 -> 0.073752169 | H17: ='Historical Financial Statemen'!H17 -> 0.07412767 | I17: ='Historical Financial Statemen'!I17 -> 0.049792941 | J17: ='Historical Financial Statemen'!J17 -> 0.048029422 | ... L17: ='Historical Financial Statemen'!L17 -> 0.26573795
B18: Depreciation % Sales | C18: ='Historical Financial Statemen'!C26 -> 0.027490234 | D18: ='Historical Financial Statemen'!D26 -> 0.026954751 | E18: ='Historical Financial Statemen'!E26 -> 0.028453629 | F18: ='Historical Financial Statemen'!F26 -> 0.028891645 | G18: ='Historical Financial Statemen'!G26 -> 0.033306066 | H18: ='Historical Financial Statemen'!H26 -> 0.033407941 | I18: ='Historical Financial Statemen'!I26 -> 0.028566628 | J18: ='Historical Financial Statemen'!J26 -> 0.025508104 | ... L18: ='Historical Financial Statemen'!L26 -> 0.021856705
B19: Operating Income % Sales | C19: =C14 -> 0.29547332 | D19: =D14 -> 0.32134677 | E19: =E14 -> 0.34753483 | F19: =F14 -> 0.3031462 | G19: =G14 -> 0.28094141 | H19: =H14 -> 0.23451681 | I19: =I14 -> 0.25738541 | J19: =J14 -> 0.29724645 | ... L19: =L14 -> 0.06567619
B21: Return on Capital Employed | C21: ='Historical Financial Statemen'!C19/('Data Sheet'!B57+B60+B59) -> 15.729223 | D21: ='Historical Financial Statemen'!D19/('Data Sheet'!C57+C60+C59) -> 12.262723 | E21: ='Historical Financial Statemen'!E19/('Data Sheet'!D57+D60+D59) -> 13.385692 | F21: ='Historical Financial Statemen'!F19/('Data Sheet'!E57+E60+E59) -> 13.093314 | G21: ='Historical Financial Statemen'!G19/('Data Sheet'!F57+F60+F59) -> 12.62586 | H21: ='Historical Financial Statemen'!H19/('Data Sheet'!G57+G60+G59) -> 10.721833 | I21: ='Historical Financial Statemen'!I19/('Data Sheet'!H57+H60+H59) -> 14.072067 | J21: ='Historical Financial Statemen'!J19/('Data Sheet'!I57+I60+I59) -> 18.417638 | ... L21: ='Historical Financial Statemen'!L19/('Data Sheet'!K57+K60+K59) -> 5.2686729
B22: Retained Earning % | C22: ='Historical Financial Statemen'!C47 -> 0.10316914 | D22: ='Historical Financial Statemen'!D47 -> 0.41738979 | E22: ='Historical Financial Statemen'!E47 -> 0.4441994 | F22: ='Historical Financial Statemen'!F47 -> 0.31890564 | G22: ='Historical Financial Statemen'!G47 -> 0 | H22: ='Historical Financial Statemen'!H47 -> 0 | I22: ='Historical Financial Statemen'!I47 -> 0 | J22: ='Historical Financial Statemen'!J47 -> 0 | ... L22: ='Historical Financial Statemen'!L47 -> 0
B23: Return on Equity % | C23: ='Historical Financial Statemen'!C37/('Data Sheet'!B57+'Data Sheet'!B58) -> 0.17870374 | D23: ='Historical Financial Statemen'!D37/('Data Sheet'!C57+'Data Sheet'!C58) -> 0.21338321 | E23: ='Historical Financial Statemen'!E37/('Data Sheet'!D57+'Data Sheet'!D58) -> 0.21535643 | F23: ='Historical Financial Statemen'!F37/('Data Sheet'!E57+'Data Sheet'!E58) -> 0.17499032 | G23: ='Historical Financial Statemen'!G37/('Data Sheet'!F57+'Data Sheet'!F58) -> 0.18030661 | H23: ='Historical Financial Statemen'!H37/('Data Sheet'!G57+'Data Sheet'!G58) -> 0.15767704 | I23: ='Historical Financial Statemen'!I37/('Data Sheet'!H57+'Data Sheet'!H58) -> 0.19568167 | J23: ='Historical Financial Statemen'!J37/('Data Sheet'!I57+'Data Sheet'!I58) -> 0.24093467 | ... L23: ='Historical Financial Statemen'!L37/('Data Sheet'!K57+'Data Sheet'!K58) -> 0.22570739
B24: Self Substained Growth Rate | C24: =C23*C22 -> 0.018436712 | D24: =D23*D22 -> 0.089063974 | E24: =E23*E22 -> 0.095661197 | F24: =F23*F22 -> 0.055805402 | G24: =G23*G22 -> 0 | H24: =H23*H22 -> 0 | I24: =I23*I22 -> 0 | J24: =J23*J22 -> 0 | ... L24: =L23*L22 -> 0
B25: Interest Coverage Ratio | C25: =('Historical Financial Statemen'!C19-'Historical Financial Statemen'!C25)/'Historical Financial Statemen'!C22 -> 148.21733 | D25: =('Historical Financial Statemen'!D19-'Historical Financial Statemen'!D25)/'Historical Financial Statemen'!D22 -> 280.30247 | E25: =('Historical Financial Statemen'!E19-'Historical Financial Statemen'!E25)/'Historical Financial Statemen'!E22 -> 131.2931 | F25: =('Historical Financial Statemen'!F19-'Historical Financial Statemen'!F25)/'Historical Financial Statemen'!F22 -> 205.23754 | G25: =('Historical Financial Statemen'!G19-'Historical Financial Statemen'!G25)/'Historical Financial Statemen'!G22 -> 170.49705 | H25: =('Historical Financial Statemen'!H19-'Historical Financial Statemen'!H25)/'Historical Financial Statemen'!H22 -> 199.27031 | I25: =('Historical Financial Statemen'!I19-'Historical Financial Statemen'!I25)/'Historical Financial Statemen'!I22 -> 260.1937 | J25: =('Historical Financial Statemen'!J19-'Historical Financial Statemen'!J25)/'Historical Financial Statemen'!J22 -> 271.06121 | ... L25: =('Historical Financial Statemen'!L19-'Historical Financial Statemen'!L25)/'Historical Financial Statemen'!L22 -> 109.78584
B27: Debtor Turnover Ratio | C27: ='Data Sheet'!B17/'Data Sheet'!B67 -> 20.442577 | D27: ='Data Sheet'!C17/'Data Sheet'!C67 -> 17.284797 | E27: ='Data Sheet'!D17/'Data Sheet'!D67 -> 16.19845 | F27: ='Data Sheet'!E17/'Data Sheet'!E67 -> 11.979238 | G27: ='Data Sheet'!F17/'Data Sheet'!F67 -> 19.273399 | H27: ='Data Sheet'!G17/'Data Sheet'!G67 -> 19.689591 | I27: ='Data Sheet'!H17/'Data Sheet'!H67 -> 24.633226 | J27: ='Data Sheet'!I17/'Data Sheet'!I67 -> 23.990173 | ... L27: ='Data Sheet'!K17/'Data Sheet'!K67 -> 15.959451
B28: Creditor Turnover Ratio | C28: ='Historical Financial Statemen'!C7/'Historical Financial Statemen'!C56 -> 4.4095324 | D28: ='Historical Financial Statemen'!D7/'Historical Financial Statemen'!D56 -> 4.5306245 | E28: ='Historical Financial Statemen'!E7/'Historical Financial Statemen'!E56 -> 3.7152199 | F28: ='Historical Financial Statemen'!F7/'Historical Financial Statemen'!F56 -> 3.8411297 | G28: ='Historical Financial Statemen'!G7/'Historical Financial Statemen'!G56 -> 4.1996201 | H28: ='Historical Financial Statemen'!H7/'Historical Financial Statemen'!H56 -> 3.7479256 | I28: ='Historical Financial Statemen'!I7/'Historical Financial Statemen'!I56 -> 4.1849768 | J28: ='Historical Financial Statemen'!J7/'Historical Financial Statemen'!J56 -> 4.3323459 | ... L28: ='Historical Financial Statemen'!L7/'Historical Financial Statemen'!L56 -> 4.2584165
B29: Inventory Turnover | C29: ='Historical Financial Statemen'!C7/'Historical Financial Statemen'!C66 -> 9.712362 | D29: ='Historical Financial Statemen'!D7/'Historical Financial Statemen'!D66 -> 10.598422 | E29: ='Historical Financial Statemen'!E7/'Historical Financial Statemen'!E66 -> 10.767268 | F29: ='Historical Financial Statemen'!F7/'Historical Financial Statemen'!F66 -> 11.979238 | G29: ='Historical Financial Statemen'!G7/'Historical Financial Statemen'!G66 -> 5.5620976 | H29: ='Historical Financial Statemen'!H7/'Historical Financial Statemen'!H66 -> 4.737587 | I29: ='Historical Financial Statemen'!I7/'Historical Financial Statemen'!I66 -> 5.5820787 | J29: ='Historical Financial Statemen'!J7/'Historical Financial Statemen'!J66 -> 6.0248123 | ... L29: ='Historical Financial Statemen'!L7/'Historical Financial Statemen'!L66 -> 4.8168218
B30: Fixed Asset Turnover | C30: ='Historical Financial Statemen'!C7/'Historical Financial Statemen'!C59 -> 2.5943642 | D30: ='Historical Financial Statemen'!D7/'Historical Financial Statemen'!D59 -> 2.6908896 | E30: ='Historical Financial Statemen'!E7/'Historical Financial Statemen'!E59 -> 2.6294508 | F30: ='Historical Financial Statemen'!F7/'Historical Financial Statemen'!F59 -> 2.4950504 | G30: ='Historical Financial Statemen'!G7/'Historical Financial Statemen'!G59 -> 2.2745326 | H30: ='Historical Financial Statemen'!H7/'Historical Financial Statemen'!H59 -> 2.1141916 | I30: ='Historical Financial Statemen'!I7/'Historical Financial Statemen'!I59 -> 2.5027058 | J30: ='Historical Financial Statemen'!J7/'Historical Financial Statemen'!J59 -> 2.743348 | ... L30: ='Historical Financial Statemen'!L7/'Historical Financial Statemen'!L59 -> 3.4308292
B31: Capital Turnover Ratio | C31: ='Historical Financial Statemen'!C7/('Historical Financial Statemen'!C53+'Historical Financial Statemen'!C54) -> 0.91828821 | D31: ='Historical Financial Statemen'!D7/('Historical Financial Statemen'!D53+'Historical Financial Statemen'!D54) -> 0.92145874 | E31: ='Historical Financial Statemen'!E7/('Historical Financial Statemen'!E53+'Historical Financial Statemen'!E54) -> 0.82743952 | F31: ='Historical Financial Statemen'!F7/('Historical Financial Statemen'!F53+'Historical Financial Statemen'!F54) -> 0.81736336 | G31: ='Historical Financial Statemen'!G7/('Historical Financial Statemen'!G53+'Historical Financial Statemen'!G54) -> 0.7566299 | H31: ='Historical Financial Statemen'!H7/('Historical Financial Statemen'!H53+'Historical Financial Statemen'!H54) -> 0.81623233 | I31: ='Historical Financial Statemen'!I7/('Historical Financial Statemen'!I53+'Historical Financial Statemen'!I54) -> 0.97100291 | J31: ='Historical Financial Statemen'!J7/('Historical Financial Statemen'!J53+'Historical Financial Statemen'!J54) -> 1.0255045 | ... L31: ='Historical Financial Statemen'!L7/('Historical Financial Statemen'!L53+'Historical Financial Statemen'!L54) -> 1.075586
B33: Debtor Days | C33: =365/C27 -> 17.854892 | D33: =365/D27 -> 21.116823 | E33: =365/E27 -> 22.53302 | F33: =365/F27 -> 30.469383 | G33: =365/G27 -> 18.938019 | H33: =365/H27 -> 18.537714 | I33: =365/I27 -> 14.817385 | J33: =365/J27 -> 15.214563 | ... L33: =365/L27 -> 22.870462
B34: Payable Days | C34: =365/C28 -> 82.775217 | D34: =365/D28 -> 80.562845 | E34: =365/E28 -> 98.24452 | F34: =365/F28 -> 95.024128 | G34: =365/G28 -> 86.912624 | H34: =365/H28 -> 97.387204 | I34: =365/I28 -> 87.216733 | J34: =365/J28 -> 84.249966 | ... L34: =365/L28 -> 85.712611
B35: Inventory Days | C35: =365/C29 -> 37.580972 | D35: =365/D29 -> 34.439089 | E35: =365/E29 -> 33.899036 | F35: =365/F29 -> 30.469383 | G35: =365/G29 -> 65.622725 | H35: =365/H29 -> 77.04344 | I35: =365/I29 -> 65.387828 | J35: =365/J29 -> 60.5828 | ... L35: =365/L29 -> 75.776106
B36: Cash Conversion Cycle | C36: =365/C30 -> 140.68958 | D36: =365/D30 -> 135.64287 | E36: =365/E30 -> 138.81226 | F36: =365/F30 -> 146.28963 | G36: =365/G30 -> 160.47253 | H36: =365/H30 -> 172.64282 | I36: =365/I30 -> 145.84215 | J36: =365/J30 -> 133.04911 | ... L36: =365/L30 -> 106.38828
B38: CFO/Sales | C38: ='Historical Financial Statemen'!C85/'Historical Financial Statemen'!C7 -> 0.25191301 | D38: ='Historical Financial Statemen'!D85/'Historical Financial Statemen'!D7 -> 0.2226218 | E38: ='Historical Financial Statemen'!E85/'Historical Financial Statemen'!E7 -> 0.24559863 | F38: ='Historical Financial Statemen'!F85/'Historical Financial Statemen'!F7 -> 0.25047797 | G38: ='Historical Financial Statemen'!G85/'Historical Financial Statemen'!G7 -> 0.30341563 | H38: ='Historical Financial Statemen'!H85/'Historical Financial Statemen'!H7 -> 0.24589174 | I38: ='Historical Financial Statemen'!I85/'Historical Financial Statemen'!I7 -> 0.25848988 | J38: ='Historical Financial Statemen'!J85/'Historical Financial Statemen'!J7 -> 0.25316195 | ... L38: ='Historical Financial Statemen'!L85/'Historical Financial Statemen'!L7 -> 0.19761471
B39: CFO/Total Assets | C39: ='Historical Financial Statemen'!C85/'Historical Financial Statemen'!C70 -> 0.19114703 | D39: ='Historical Financial Statemen'!D85/'Historical Financial Statemen'!D70 -> 0.17032712 | E39: ='Historical Financial Statemen'!E85/'Historical Financial Statemen'!E70 -> 0.16610918 | F39: ='Historical Financial Statemen'!F85/'Historical Financial Statemen'!F70 -> 0.16877839 | G39: ='Historical Financial Statemen'!G85/'Historical Financial Statemen'!G70 -> 0.19382815 | H39: ='Historical Financial Statemen'!H85/'Historical Financial Statemen'!H70 -> 0.16420655 | I39: ='Historical Financial Statemen'!I85/'Historical Financial Statemen'!I70 -> 0.20306746 | J39: ='Historical Financial Statemen'!J85/'Historical Financial Statemen'!J70 -> 0.2091786 | ... L39: ='Historical Financial Statemen'!L85/'Historical Financial Statemen'!L70 -> 0.16914254
B40: CFO/Total Debt | C40: ='Historical Financial Statemen'!C85/'Historical Financial Statemen'!C55 -> 117.84435 | D40: ='Historical Financial Statemen'!D85/'Historical Financial Statemen'!D55 -> 208.24584 | E40: ='Historical Financial Statemen'!E85/'Historical Financial Statemen'!E55 -> 297.07684 | F40: ='Historical Financial Statemen'!F85/'Historical Financial Statemen'!F55 -> 900.89286 | G40: ='Historical Financial Statemen'!G85/'Historical Financial Statemen'!G55 -> 54.009731 | H40: ='Historical Financial Statemen'!H85/'Historical Financial Statemen'!H55 -> 44.721781 | I40: ='Historical Financial Statemen'!I85/'Historical Financial Statemen'!I55 -> 62.844772 | J40: ='Historical Financial Statemen'!J85/'Historical Financial Statemen'!J55 -> 58.665534 | ... L40: ='Historical Financial Statemen'!L85/'Historical Financial Statemen'!L55 -> 52.312504

Sheet Sheet1
A1: 41699 | B1: 42064 | C1: 42430 | D1: 42795 | E1: 43160 | F1: 43525 | G1: 43891 | H1: 44256 | I1: 44621 | J1: 44986 | K1: 45352 | L1: 45717
A2: Cash from Operating Activity - | B2: 7344 | C2: 9843 | D2: 9799 | E2: 10627 | F2: 13169 | G2: 12583 | H2: 14690 | I2: 12527 | J2: 15776 | K2: 18878 | L2: 17179 | M2: 17627
A3: Profit from operations | B3: 13172 | C3: 14261 | D3: 15154 | E3: 16075 | F3: 17433 | G3: 18862 | H3: 19416 | I3: 17326 | J3: 20857 | K3: 26052 | L3: 26635 | M3: 26719
A4: Receivables | B4: -1546 | C4: 558 | D4: -207 | E4: -870 | F4: -964 | G4: -755 | H4: 1411 | I4: -66 | J4: -732 | K4: -884 | L4: -934 | M4: -1023
A5: Inventory | B5: -755 | C5: -505 | D5: -693 | E5: 593 | F5: 602 | G5: -359 | H5: -508 | I5: -1460 | J5: -466 | K5: -1098 | L5: -2545 | M5: -2975
A6: Payables | B6: 456 | C6: -23 | D6: 622 | E6: 321 | F6: 2098 | G6: 639 | H6: -607 | I6: 1112 | J6: 1099 | K6: 1058 | L6: 141 | M6: 1256
A7: Working capital changes | B7: -1844 | C7: 31 | D7: -277 | E7: 44 | F7: 1736 | G7: -476 | H7: 296 | I7: -413 | J7: -100 | K7: -924 | L7: -3337 | M7: -2742
A8: Direct taxes | B8: -3984 | C8: -4449 | D8: -5078 | E8: -5492 | F8: -6000 | G8: -5803 | H8: -5023 | I8: -4387 | J8: -4982 | K8: -6250 | L8: -6120 | M8: -6350
A9: Cash from Investing Activity - | B9: -3254 | C9: -5275 | D9: -3921 | E9: -3251 | F9: -7114 | G9: -5546 | H9: -6174 | I9: 5740 | J9: -2238 | K9: -5732 | L9: 1563 | M9: -564
A10: Fixed assets purchased | B10: -2887 | C10: -3300 | D10: -2348 | E10: -3122 | F10: -2878 | G10: -3169 | H10: -2441 | I10: -1837 | J10: -2142 | K10: -2743 | L10: -3563 | M10: -2279
A11: Fixed assets sold | B11: 38 | C11: 9 | D11: 8 | E11: 50 | F11: 80 | G11: 28 | H11: 27 | I11: 3 | J11: 133 | K11: 49 | L11: 107 | M11: 175
A12: Investments purchased | B12: -94242 | C12: -98742 | D12: -154081 | E12: -85683 | F12: -98330 | G12: -94187 | H12: -79835 | I12: -57553 | J12: -69776 | K12: -80932 | L12: -75107 | M12: -66373
A13: Investments sold | B13: 93293 | C13: 99658 | D13: 150651 | E13: 81034 | F13: 95017 | G13: 92454 | H13: 75835 | I13: 62797 | J13: 70992 | K13: 77230 | L13: 77830 | M13: 67311
... A28: Net Cash Flow | B28: -32 | C28: -93 | D28: 266 | E28: 75 | F28: -166 | G28: 169 | H28: 334 | I28: -367 | J28: -43 | K28: 139 | L28: 191 | M28: 26

Sheet Forecasting
B3: ="Forecasting - "&'Data Sheet'!B1 -> Forecasting - ITC LTD | G3: Forecasting - ITC LTD
B4: Year Weightage | C4: Year | D4: Sales | E4: YoY Growth | G4: Year Weightage | H4: Year | I4: EBITDA | J4: YoY Growth
B5: 1 | C5: 42460 | D5: 39192.1 | G5: 1 | H5: 42460 | I5: 12657.62
B6: 2 | C6: 42825 | D6: 42767.6 | E6: =(D6/D5)-1 -> 0.09123012 | G6: 2 | H6: 42825 | I6: 14896.02 | J6: =I6/I5-1 -> 0.17684209
B7: 3 | C7: 43190 | D7: 43448.94 | E7: =(D7/D6)-1 -> 0.015931219 | G7: 3 | H7: 43190 | I7: 16336.3 | J7: =I7/I6-1 -> 0.096688914
B8: 4 | C8: 43555 | D8: 48339.58 | E8: =(D8/D7)-1 -> 0.11256063 | G8: 4 | H8: 43555 | I8: 16050.57 | J8: =I8/I7-1 -> -0.017490497
B9: 5 | C9: 43921 | D9: 49387.7 | E9: =(D9/D8)-1 -> 0.021682439 | G9: 5 | H9: 43921 | I9: 15519.96 | J9: =I9/I8-1 -> -0.033058639
B10: 6 | C10: 44286 | D10: 49257.45 | E10: =(D10/D9)-1 -> -0.0026372963 | G10: 6 | H10: 44286 | I10: 13197.29 | J10: =I10/I9-1 -> -0.14965696
B11: 7 | C11: 44651 | D11: 60644.54 | E11: =(D11/D10)-1 -> 0.23117498 | G11: 7 | H11: 44651 | I11: 17341.43 | J11: =I11/I10-1 -> 0.31401447
B12: 8 | C12: 45016 | D12: 70919.03 | E12: =(D12/D11)-1 -> 0.16942152 | G12: 8 | H12: 45016 | I12: 22889.44 | J12: =I12/I11-1 -> 0.31992806
B13: 9 | C13: 45382 | D13: 67931.94 | E13: =(D13/D12)-1 -> -0.042119724 | G13: 9 | H13: 45382 | I13: 21121.54 | J13: =I13/I12-1 -> -0.07723649
B14: 10 | C14: 45747 | D14: 75323.34 | E14: =(D14/D13)-1 -> 0.10880596 | G14: 10 | H14: 45747 | I14: 6593.27 | J14: =I14/I13-1 -> -0.68784142
B15: 11 | C15: 46112 | D15: =FORECAST(B15,D5:D14,B5:B14) -> 77236.776 | E15: =(D15/D14)-1 -> 0.025402963 | G15: 11 | H15: 46112 | I15: =FORECAST(G15,I5:I14,G5:G14) -> 16437.514 | J15: =I15/I14-1 -> 1.4930746
B16: 12 | C16: 46477 | D16: =FORECAST(B16,D6:D15,B6:B15) -> 82101.898 | E16: =(D16/D15)-1 -> 0.062989714 | G16: 12 | H16: 46477 | I16: =FORECAST(G16,I6:I15,G6:G15) -> 15947.656 | J16: =I16/I15-1 -> -0.029801246
B17: 13 | C17: 46843 | D17: =FORECAST(B17,D7:D16,B7:B16) -> 87330.225 | E17: =(D17/D16)-1 -> 0.063680943 | G17: 13 | H17: 46843 | I17: =FORECAST(G17,I7:I16,G7:G16) -> 15606.768 | J17: =I17/I16-1 -> -0.021375432
B18: 14 | C18: 47208 | D18: =FORECAST(B18,D8:D17,B8:B17) -> 92209.286 | E18: =(D18/D17)-1 -> 0.055869098 | G18: 14 | H18: 47208 | I18: =FORECAST(G18,I8:I17,G8:G17) -> 15443.49 | J18: =I18/I17-1 -> -0.010461975
B19: 15 | C19: 47573 | D19: =FORECAST(B19,D9:D18,B9:B18) -> 97418.723 | E19: =(D19/D18)-1 -> 0.056495796 | G19: 15 | H19: 47573 | I19: =FORECAST(G19,I9:I18,G9:G18) -> 15187.342 | J19: =I19/I18-1 -> -0.016586136

Sheet Data Sheet
A1: COMPANY NAME | B1: ITC LTD | E1: =IF(B2<>B3, "A NEW VERSION OF THE WORKSHEET IS AVAILABLE", "")
A2: LATEST VERSION | B2: 2.1 | E2: PLEASE DO NOT MAKE ANY CHANGES TO THIS SHEET
A3: CURRENT VERSION | B3: 2.1
A5: META
A6: Number of shares | B6: =IF(B9>0, B9/B8, 0) -> 1252.8172
A7: Face Value | B7: 1
A8: Current Price | B8: 413.75
A9: Market Capitalization | B9: 518353.12
A15: PROFIT & LOSS
A16: Report Date | B16: 42460 | C16: 42825 | D16: 43190 | E16: 43555 | F16: 43921 | G16: 44286 | H16: 44651 | I16: 45016 | J16: 45382 | K16: 45747
A17: Sales | B17: 39192.1 | C17: 42767.6 | D17: 43448.94 | E17: 48339.58 | F17: 49387.7 | G17: 49257.45 | H17: 60644.54 | I17: 70919.03 | J17: 67931.94 | K17: 75323.34
A18: Raw Material Cost | B18: 13763.88 | C18: 15456.59 | D18: 14827.72 | E18: 17623.52 | F18: 18048.6 | G18: 20776.71 | H18: 27071.07 | I18: 29364.36 | J18: 27348.57 | K18: 32704.37
A19: Change in Inventory | B19: 195.38 | C19: -592.57 | D19: -1027.76 | E19: 203.19 | F19: 703.13 | G19: 645.27 | H19: 686 | I19: 358.59 | J19: 367.77 | K19: 725.65
A20: Power and Fuel | B20: 571.88 | C20: 584.33 | D20: 653.5 | E20: 746.73 | F20: 780.85 | G20: 699.56 | H20: 889.77 | I20: 1232.34 | J20: 952.9 | K20: 975.35
A21: Other Mfr. Exp | B21: 1581.59 | C21: 1683.9 | D21: 1697.62 | E21: 1871.01 | F21: 1908.29 | G21: 1587.18 | H21: 1887.67 | I21: 2327.8 | J21: 2183.76 | K21: 2345.36
A22: Employee Cost | B22: 3440.97 | C22: 3631.73 | D22: 3760.9 | E22: 4177.88 | F22: 4295.79 | G22: 4463.33 | H22: 4890.55 | I22: 5736.22 | J22: 5548.53 | K22: 6169.78
A23: Selling and admin | B23: 4261.78 | C23: 4179.74 | D23: 3954.87 | E23: 4546.39 | F23: 4488.63 | G23: 4236.77 | H23: 4858.38 | I23: 5604.08 | J23: 5312.45 | K23: 5793.29
A24: Other Expenses | B24: 1235.89 | C24: 1169.23 | D24: 1005.98 | E24: 1039.85 | F24: 1225.13 | G24: 1074.39 | H24: 1109.95 | I24: 1308.56 | J24: 1765.97 | K24: 2221.39
A25: Other Income | B25: 1483.11 | C25: 1758.63 | D25: 2239.81 | E25: 2080.44 | F25: 2417.32 | G25: 2576.95 | H25: 1909.72 | I25: 2097.64 | J25: 3330.45 | K25: 17794.88
A26: Depreciation | B26: 1077.4 | C26: 1152.79 | D26: 1236.28 | E26: 1396.61 | F26: 1644.91 | G26: 1645.59 | H26: 1732.41 | I26: 1809.01 | J26: 1518.05 | K26: 1646.32
A27: Interest | B27: 78.13 | C27: 49.03 | D27: 115.01 | E27: 71.4 | F27: 81.38 | G27: 57.97 | H27: 59.99 | I27: 77.77 | J27: 39.11 | K27: 45.06
... A31: Dividend Amount | B31: 6840.12 | C31: 5770.02 | D31: 6285.21 | E31: 7048.7 | F31: 12476.58 | G31: 13231.96 | H31: 14171.8 | I31: 19263.4 | J31: 17166.46 | K31: 17957.73
A33: EBiTDA | B33: =B30+B29+B27+B26 -> 15858.19 | C33: =C30+C29+C27+C26 -> 17040.35 | D33: =D30+D29+D27+D26 -> 18538.92 | E33: =E30+E29+E27+E26 -> 20374.26 | F33: =F30+F29+F27+F26 -> 21474.31 | G33: =G30+G29+G27+G26 -> 19420.04 | H33: =H30+H29+H27+H26 -> 22272.4 | I33: =I30+I29+I27+I26 -> 27516.84 | ... K33: =K30+K29+K27+K26 -> 43328.48
A40: Quarters
A41: Report Date | B41: 45016 | C41: 45107 | D41: 45199 | E41: 45291 | F41: 45382 | G41: 45473 | H41: 45565 | I41: 45657 | J41: 45747 | K41: 45838
A42: Sales | B42: 17634.89 | C42: 17164.46 | D42: 17774.47 | E42: 17195.24 | F42: 17037.8 | G42: 17777.81 | H42: 19990.36 | I42: 18790.17 | J42: 18765 | K42: 21494.79
A43: Expenses | B43: 11010.89 | C43: 10494.39 | D43: 11320.23 | E43: 10985.01 | F43: 10735.73 | G43: 11232.97 | H43: 13438.28 | I43: 12428.27 | J43: 12245.61 | K43: 14678.32
A44: Other Income | B44: 682.52 | C44: 722.3 | D44: 673.5 | E44: 820.26 | F44: 868 | G44: 771.13 | H44: 690.31 | I44: 803.4 | J44: 15391.28 | K44: 750.97
A45: Depreciation | B45: 461.4 | C45: 442.46 | D45: 453.04 | E45: 384.04 | F45: 385.09 | G45: 403.13 | H45: 416.18 | I45: 415.98 | J45: 411.03 | K45: 422.96
A46: Interest | B46: 12.15 | C46: 9.9 | D46: 9.87 | E46: 11.94 | F46: 10.72 | G46: 9.6 | H46: 14.73 | I46: 9.82 | J46: 10.91 | K46: 16.47
A47: Profit before tax | B47: 6832.97 | C47: 6940.01 | D47: 6664.83 | E47: 6634.51 | F47: 6774.26 | G47: 6903.24 | H47: 6811.48 | I47: 6739.5 | J47: 21488.73 | K47: 7128.01
A48: Tax | B48: 1607.95 | C48: 1759.89 | D48: 1700.31 | E48: 1227.99 | F48: 1583.55 | G48: 1726.25 | H48: 1757.05 | I48: 1726.32 | J48: 1680.85 | K48: 1784.6
A49: Net profit | B49: 5175.48 | C49: 5104.93 | D49: 4898.07 | E49: 5335.23 | F49: 5120.55 | G49: 5091.59 | H49: 4992.87 | I49: 4934.8 | J49: 19727.37 | K49: 5244.2
A50: Operating Profit | B50: 6624 | C50: 6670.07 | D50: 6454.24 | E50: 6210.23 | F50: 6302.07 | G50: 6544.84 | H50: 6552.08 | I50: 6361.9 | J50: 6519.39 | K50: 6816.47
A55: BALANCE SHEET
A56: Report Date | B56: 42460 | C56: 42825 | D56: 43190 | E56: 43555 | F56: 43921 | G56: 44286 | H56: 44651 | I56: 45016 | J56: 45382 | K56: 45747
A57: Equity Share Capital | B57: 804.72 | C57: 1214.74 | D57: 1220.43 | E57: 1225.86 | F57: 1229.22 | G57: 1230.88 | H57: 1232.33 | I57: 1242.8 | J57: 1248.47 | K57: 1251.41
A58: Reserves | B58: 41874.8 | C58: 45198.19 | D58: 51289.68 | E58: 57915.01 | F58: 64044.04 | G58: 59116.46 | H58: 61223.24 | I58: 67912.46 | J58: 73258.53 | K58: 68778.64
A59: Borrowings | B59: 83.78 | C59: 45.72 | D59: 35.92 | E59: 13.44 | F59: 277.45 | G59: 270.83 | H59: 249.44 | I59: 306.04 | J59: 303.43 | K59: 284.54
A60: Other Liabilities | B60: 8888.04 | C60: 9439.67 | D60: 11694.85 | E60: 12584.73 | F60: 11760.04 | G60: 13142.59 | H60: 14491.01 | I60: 16369.66 | J60: 16943.54 | K60: 17688.11
...

Sheet Quarters
A1: ='Profit & Loss'!A1 -> ITC LTD | E1: =UPDATE | J1: SCREENER.IN
A3: Narration | B3: ='Data Sheet'!B41 -> 45016 | C3: ='Data Sheet'!C41 -> 45107 | D3: ='Data Sheet'!D41 -> 45199 | E3: ='Data Sheet'!E41 -> 45291 | F3: ='Data Sheet'!F41 -> 45382 | G3: ='Data Sheet'!G41 -> 45473 | H3: ='Data Sheet'!H41 -> 45565 | I3: ='Data Sheet'!I41 -> 45657 | ... K3: ='Data Sheet'!K41 -> 45838
A4: Sales | B4: ='Data Sheet'!B42 -> 17634.89 | C4: ='Data Sheet'!C42 -> 17164.46 | D4: ='Data Sheet'!D42 -> 17774.47 | E4: ='Data Sheet'!E42 -> 17195.24 | F4: ='Data Sheet'!F42 -> 17037.8 | G4: ='Data Sheet'!G42 -> 17777.81 | H4: ='Data Sheet'!H42 -> 19990.36 | I4: ='Data Sheet'!I42 -> 18790.17 | ... K4: ='Data Sheet'!K42 -> 21494.79
A5: Expenses | B5: ='Data Sheet'!B43 -> 11010.89 | C5: ='Data Sheet'!C43 -> 10494.39 | D5: ='Data Sheet'!D43 -> 11320.23 | E5: ='Data Sheet'!E43 -> 10985.01 | F5: ='Data Sheet'!F43 -> 10735.73 | G5: ='Data Sheet'!G43 -> 11232.97 | H5: ='Data Sheet'!H43 -> 13438.28 | I5: ='Data Sheet'!I43 -> 12428.27 | ... K5: ='Data Sheet'!K43 -> 14678.32
A6: Operating Profit | B6: ='Data Sheet'!B50 -> 6624 | C6: ='Data Sheet'!C50 -> 6670.07 | D6: ='Data Sheet'!D50 -> 6454.24 | E6: ='Data Sheet'!E50 -> 6210.23 | F6: ='Data Sheet'!F50 -> 6302.07 | G6: ='Data Sheet'!G50 -> 6544.84 | H6: ='Data Sheet'!H50 -> 6552.08 | I6: ='Data Sheet'!I50 -> 6361.9 | ... K6: ='Data Sheet'!K50 -> 6816.47
A7: Other Income | B7: ='Data Sheet'!B44 -> 682.52 | C7: ='Data Sheet'!C44 -> 722.3 | D7: ='Data Sheet'!D44 -> 673.5 | E7: ='Data Sheet'!E44 -> 820.26 | F7: ='Data Sheet'!F44 -> 868 | G7: ='Data Sheet'!G44 -> 771.13 | H7: ='Data Sheet'!H44 -> 690.31 | I7: ='Data Sheet'!I44 -> 803.4 | ... K7: ='Data Sheet'!K44 -> 750.97
A8: Depreciation | B8: ='Data Sheet'!B45 -> 461.4 | C8: ='Data Sheet'!C45 -> 442.46 | D8: ='Data Sheet'!D45 -> 453.04 | E8: ='Data Sheet'!E45 -> 384.04 | F8: ='Data Sheet'!F45 -> 385.09 | G8: ='Data Sheet'!G45 -> 403.13 | H8: ='Data Sheet'!H45 -> 416.18 | I8: ='Data Sheet'!I45 -> 415.98 | ... K8: ='Data Sheet'!K45 -> 422.96
A9: Interest | B9: ='Data Sheet'!B46 -> 12.15 | C9: ='Data Sheet'!C46 -> 9.9 | D9: ='Data Sheet'!D46 -> 9.87 | E9: ='Data Sheet'!E46 -> 11.94 | F9: ='Data Sheet'!F46 -> 10.72 | G9: ='Data Sheet'!G46 -> 9.6 | H9: ='Data Sheet'!H46 -> 14.73 | I9: ='Data Sheet'!I46 -> 9.82 | ... K9: ='Data Sheet'!K46 -> 16.47
A10: Profit before tax | B10: ='Data Sheet'!B47 -> 6832.97 | C10: ='Data Sheet'!C47 -> 6940.01 | D10: ='Data Sheet'!D47 -> 6664.83 | E10: ='Data Sheet'!E47 -> 6634.51 | F10: ='Data Sheet'!F47 -> 6774.26 | G10: ='Data Sheet'!G47 -> 6903.24 | H10: ='Data Sheet'!H47 -> 6811.48 | I10: ='Data Sheet'!I47 -> 6739.5 | ... K10: ='Data Sheet'!K47 -> 7128.01
A11: Tax | B11: ='Data Sheet'!B48 -> 1607.95 | C11: ='Data Sheet'!C48 -> 1759.89 | D11: ='Data Sheet'!D48 -> 1700.31 | E11: ='Data Sheet'!E48 -> 1227.99 | F11: ='Data Sheet'!F48 -> 1583.55 | G11: ='Data Sheet'!G48 -> 1726.25 | H11: ='Data Sheet'!H48 -> 1757.05 | I11: ='Data Sheet'!I48 -> 1726.32 | ... K11: ='Data Sheet'!K48 -> 1784.6
A12: Net profit | B12: ='Data Sheet'!B49 -> 5175.48 | C12: ='Data Sheet'!C49 -> 5104.93 | D12: ='Data Sheet'!D49 -> 4898.07 | E12: ='Data Sheet'!E49 -> 5335.23 | F12: ='Data Sheet'!F49 -> 5120.55 | G12: ='Data Sheet'!G49 -> 5091.59 | H12: ='Data Sheet'!H49 -> 4992.87 | I12: ='Data Sheet'!I49 -> 4934.8 | ... K12: ='Data Sheet'!K49 -> 5244.2
A14: OPM | B14: =IF(B4>0,B6/B4,"") -> 0.37561901 | C14: =IF(C4>0,C6/C4,"") -> 0.38859772 | D14: =IF(D4>0,D6/D4,"") -> 0.36311856 | E14: =IF(E4>0,E6/E4,"") -> 0.36115983 | F14: =IF(F4>0,F6/F4,"") -> 0.36988754 | G14: =IF(G4>0,G6/G4,"") -> 0.36814658 | H14: =IF(H4>0,H6/H4,"") -> 0.32776198 | I14: =IF(I4>0,I6/I4,"") -> 0.33857597 | ... K14: =IF(K4>0,K6/K4,"") -> 0.31712196

Sheet WACC
B3: Weighted Average Cost of Capital
G6: Debt / | H6: Debt / | I6: Levered | J6: Unlevered
B7: Name of the Company | C7: Country | D7: Total Debt | E7: Total Equity | F7: Tax Rate 1 | G7: Equity | H7: Capital | I7: Beta 2 | J7: Beta 3
B9: ITC | C9: India | D9: 91.26 | E9: 70030.05 | F9: 0.25 | G9: =D9/E9 -> 0.0013031549 | H9: =D9/(D9+E9) -> 0.0013014589 | I9: ='Reg. Beta'!J13 -> 0.63865833 | J9: =I9/(1+(1-F9)*G9) -> 0.63803474
B10: Hind. Unilever | C10: India | D10: 1139 | E10: 611503.9 | F10: 0.25 | G10: =D10/E10 -> 0.001862621 | H10: =D10/(D10+E10) -> 0.0018591581 | I10: 1 | J10: =I10/(1+(1-F10)*G10) -> 0.99860498
B11: Nestle India | C11: India | D11: 279.9 | E11: 182975 | F11: 0.25 | G11: =D11/E11 -> 0.0015297172 | H11: =D11/(D11+E11) -> 0.0015273807 | I11: 1 | J11: =I11/(1+(1-F11)*G11) -> 0.99885403
B12: Britannia Inds. | C12: India | D12: 3037.7 | E12: 110690 | F12: 0.25 | G12: =D12/E12 -> 0.02744331 | H12: =D12/(D12+E12) -> 0.026710291 | I12: 1 | J12: =I12/(1+(1-F12)*G12) -> 0.97983261
B13: Godrej Consumer | C13: India | D13: 1164.5 | E13: 96256.4 | F13: 0.25 | G13: =D13/E13 -> 0.012097897 | H13: =D13/(D13+E13) -> 0.011953287 | I13: 1 | J13: =I13/(1+(1-F13)*G13) -> 0.99100816
B14: Dabur India | C14: India | D14: 1068.1 | E14: 94940.4 | F14: 0.25 | G14: =D14/E14 -> 0.011250216 | H14: =D14/(D14+E14) -> 0.011125057 | I14: 1 | J14: =I14/(1+(1-F14)*G14) -> 0.99163294
E16: Average | F16: =AVERAGE(F10:F14) -> 0.25 | G16: =AVERAGE(G10:G14) -> 0.010836752 | H16: =AVERAGE(H10:H14) -> 0.010635035 | I16: =AVERAGE(I10:I14) -> 1 | J16: =AVERAGE(J10:J14) -> 0.99198654
E17: Median | F17: =MEDIAN(F10:F14) -> 0.25 | G17: =MEDIAN(G10:G14) -> 0.011250216 | H17: =MEDIAN(H10:H14) -> 0.011125057 | I17: =MEDIAN(I10:I14) -> 1 | J17: =MEDIAN(J10:J14) -> 0.99163294
